<?xml version="1.0" encoding="UTF-8"?>
<!-- Generated by org.testng.reporters.JUnitReportReporter -->
<testsuite hostname="TCLIN53" failures="2" tests="10" name="RerunFailedcases.RerunUsingTestNG" time="0.035" errors="0" timestamp="2023-04-28T12:17:24 IST" skipped="8">
  <testcase classname="RerunFailedcases.RerunUsingTestNG" name="Testcase1" time="0.002">
    <failure message="expected [false] but found [true]" type="java.lang.AssertionError">
      <![CDATA[java.lang.AssertionError: expected [false] but found [true]
at org.testng.Assert.fail(Assert.java:99)
at org.testng.Assert.failNotEquals(Assert.java:1037)
at org.testng.Assert.assertEqualsImpl(Assert.java:140)
at org.testng.Assert.assertEquals(Assert.java:122)
at org.testng.Assert.assertEquals(Assert.java:819)
at org.testng.Assert.assertEquals(Assert.java:829)
at RerunFailedcases.RerunUsingTestNG.Testcase1(RerunUsingTestNG.java:10)
at java.base/jdk.internal.reflect.NativeMethodAccessorImpl.invoke0(Native Method)
at java.base/jdk.internal.reflect.NativeMethodAccessorImpl.invoke(NativeMethodAccessorImpl.java:62)
at java.base/jdk.internal.reflect.DelegatingMethodAccessorImpl.invoke(DelegatingMethodAccessorImpl.java:43)
at java.base/java.lang.reflect.Method.invoke(Method.java:566)
at org.testng.internal.MethodInvocationHelper.invokeMethod(MethodInvocationHelper.java:133)
at org.testng.internal.TestInvoker.invokeMethod(TestInvoker.java:598)
at org.testng.internal.TestInvoker.retryFailed(TestInvoker.java:213)
at org.testng.internal.MethodRunner.runInSequence(MethodRunner.java:58)
at org.testng.internal.TestInvoker$MethodInvocationAgent.invoke(TestInvoker.java:824)
at org.testng.internal.TestInvoker.invokeTestMethods(TestInvoker.java:146)
at org.testng.internal.TestMethodWorker.invokeTestMethods(TestMethodWorker.java:146)
at org.testng.internal.TestMethodWorker.run(TestMethodWorker.java:128)
at java.base/java.util.concurrent.ThreadPoolExecutor.runWorker(ThreadPoolExecutor.java:1128)
at java.base/java.util.concurrent.ThreadPoolExecutor$Worker.run(ThreadPoolExecutor.java:628)
at java.base/java.lang.Thread.run(Thread.java:834)
]]>
    </failure>
  </testcase> <!-- Testcase1 -->
  <system-out/>
  <testcase classname="RerunFailedcases.RerunUsingTestNG" name="Testcase1" time="0.011">
    <skipped/>
  </testcase> <!-- Testcase1 -->
  <system-out/>
  <testcase classname="RerunFailedcases.RerunUsingTestNG" name="Testcase1" time="0.001">
    <skipped/>
  </testcase> <!-- Testcase1 -->
  <system-out/>
  <testcase classname="RerunFailedcases.RerunUsingTestNG" name="Testcase2" time="0.011">
    <skipped/>
  </testcase> <!-- Testcase2 -->
  <system-out/>
  <testcase classname="RerunFailedcases.RerunUsingTestNG" name="Testcase1" time="0.002">
    <skipped/>
  </testcase> <!-- Testcase1 -->
  <system-out/>
  <testcase classname="RerunFailedcases.RerunUsingTestNG" name="Testcase2" time="0.002">
    <failure message="expected [false] but found [true]" type="java.lang.AssertionError">
      <![CDATA[java.lang.AssertionError: expected [false] but found [true]
at org.testng.Assert.fail(Assert.java:99)
at org.testng.Assert.failNotEquals(Assert.java:1037)
at org.testng.Assert.assertEqualsImpl(Assert.java:140)
at org.testng.Assert.assertEquals(Assert.java:122)
at org.testng.Assert.assertEquals(Assert.java:819)
at org.testng.Assert.assertEquals(Assert.java:829)
at RerunFailedcases.RerunUsingTestNG.Testcase2(RerunUsingTestNG.java:15)
at java.base/jdk.internal.reflect.NativeMethodAccessorImpl.invoke0(Native Method)
at java.base/jdk.internal.reflect.NativeMethodAccessorImpl.invoke(NativeMethodAccessorImpl.java:62)
at java.base/jdk.internal.reflect.DelegatingMethodAccessorImpl.invoke(DelegatingMethodAccessorImpl.java:43)
at java.base/java.lang.reflect.Method.invoke(Method.java:566)
at org.testng.internal.MethodInvocationHelper.invokeMethod(MethodInvocationHelper.java:133)
at org.testng.internal.TestInvoker.invokeMethod(TestInvoker.java:598)
at org.testng.internal.TestInvoker.retryFailed(TestInvoker.java:213)
at org.testng.internal.MethodRunner.runInSequence(MethodRunner.java:58)
at org.testng.internal.TestInvoker$MethodInvocationAgent.invoke(TestInvoker.java:824)
at org.testng.internal.TestInvoker.invokeTestMethods(TestInvoker.java:146)
at org.testng.internal.TestMethodWorker.invokeTestMethods(TestMethodWorker.java:146)
at org.testng.internal.TestMethodWorker.run(TestMethodWorker.java:128)
at java.base/java.util.concurrent.ThreadPoolExecutor.runWorker(ThreadPoolExecutor.java:1128)
at java.base/java.util.concurrent.ThreadPoolExecutor$Worker.run(ThreadPoolExecutor.java:628)
at java.base/java.lang.Thread.run(Thread.java:834)
]]>
    </failure>
  </testcase> <!-- Testcase2 -->
  <system-out/>
  <testcase classname="RerunFailedcases.RerunUsingTestNG" name="Testcase2" time="0.001">
    <skipped/>
  </testcase> <!-- Testcase2 -->
  <system-out/>
  <testcase classname="RerunFailedcases.RerunUsingTestNG" name="Testcase2" time="0.001">
    <skipped/>
  </testcase> <!-- Testcase2 -->
  <system-out/>
  <testcase classname="RerunFailedcases.RerunUsingTestNG" name="Testcase2" time="0.002">
    <skipped/>
  </testcase> <!-- Testcase2 -->
  <system-out/>
  <testcase classname="RerunFailedcases.RerunUsingTestNG" name="Testcase1" time="0.002">
    <skipped/>
  </testcase> <!-- Testcase1 -->
  <system-out/>
</testsuite> <!-- RerunFailedcases.RerunUsingTestNG -->
